------
 > [4/4] RUN python3 test.py:
#8 0.629 ..E.
#8 0.635 ======================================================================
#8 0.635 ERROR: test_case2 (__main__.TestLoggingConfig)
#8 0.635 ----------------------------------------------------------------------
#8 0.636 Traceback (most recent call last):
#8 0.636   File "/tests/test.py", line 13, in test_case2
#8 0.636     fileConfig("case2.ini")
#8 0.636   File "/usr/local/lib/python3.9/logging/config.py", line 71, in fileConfig
#8 0.636     formatters = _create_formatters(cp)
#8 0.636   File "/usr/local/lib/python3.9/logging/config.py", line 118, in _create_formatters
#8 0.636     c = _resolve(class_name)
#8 0.636   File "/usr/local/lib/python3.9/logging/config.py", line 95, in _resolve
#8 0.636     __import__(used)
#8 0.636 ModuleNotFoundError: No module named 'bar.logging.FooBarFormatter'; 'bar.logging' is not a package
#8 0.636
#8 0.636 ----------------------------------------------------------------------
#8 0.636 Ran 4 tests in 0.016s
#8 0.636
#8 0.637 FAILED (errors=1)
------
executor failed running [/bin/sh -c python3 test.py]: exit code: 1
